<?xml version='1.0' encoding='UTF-8'?>
<sdf version="1.6">
  <model name="orca4">
    <pose>0 0 0 0 0 0</pose>

    <!-- BlueROV2 thruster reference: http://www.ardusub.com/introduction/features.html -->

    <link name="base_link">
      <inertial>
        <pose>0.0 0.0 0.011 0 0 0</pose>
        <mass>13.0</mass>
        <inertia>
          <ixx>0.26</ixx>
          <ixy>0</ixy>
          <ixz>0</ixz>
          <iyy>0.23</iyy>
          <iyz>0</iyz>
          <izz>0.37</izz>
        </inertia>
      </inertial>

      <visual name="base_link_visual">
        <geometry>
          <mesh>
            <uri>model://orca4/meshes/bluerov2_heavy.dae</uri>
            <scale>0.025 0.025 0.025</scale>
          </mesh>
        </geometry>
      </visual>

      <!-- Collision volume * fluid_density == displaced mass, used by BuoyancyPlugin -->
      <collision name="base_link_collision">
        <pose>0.0 0.0 0.06 0 0 0</pose>
        <geometry>
          <box>
            <size>0.457 0.575 0.05</size>
          </box>
        </geometry>
      </collision>

      <!-- IMU sensor gyro and accel data will be sent to ArduSub -->
      <sensor name="imu_sensor" type="imu">
        <!-- Transform from the Gazebo body frame (x-forward, y-left, z-up)
             to the ArduPilot body frame (x-forward, y-right, z-down) -->
        <pose>0 0 0 3.142 0 0</pose>
        <always_on>1</always_on>
        <update_rate>1000.0</update_rate>
      </sensor>



    </link>

    <!-- Hydrodynamics plugin -->
    <plugin
        filename="gz-sim-hydrodynamics-system"
        name="gz::sim::systems::Hydrodynamics">
      <link_name>base_link</link_name>
      <water_density>1000.0</water_density>
      <!-- Added mass: -->
      <xDotU>0</xDotU>
      <yDotV>0</yDotV>
      <zDotW>0</zDotW>
      <kDotP>0</kDotP>
      <mDotQ>0</mDotQ>
      <nDotR>0</nDotR>
      <!-- First order stability derivative: -->
      <xU>0</xU>
      <yV>0</yV>
      <zW>0</zW>
      <kP>0</kP>
      <mQ>0</mQ>
      <nR>0</nR>
      <!-- Second order stability derivative: -->
      <xUabsU>-58.42</xUabsU>
      <yVabsV>-55.137</yVabsV>
      <zWabsW>-124.818</zWabsW>
      <kPabsP>-4.0</kPabsP>
      <mQabsQ>-4.0</mQabsQ>
      <nRabsR>-4.0</nRabsR>
    </plugin>

    <link name="thruster1">
      <pose>0.14 -0.092 0.0 -1.571 1.571 -0.785</pose>
      <visual name="thruster_prop_visual">
        <pose>0 0 0 -1.571 0 0</pose>
        <geometry>
          <mesh>
            <uri>model://orca4/meshes/t200_ccw_prop.dae</uri>
          </mesh>
        </geometry>
      </visual>
      <inertial>
        <mass>0.002</mass>
        <inertia>
          <ixx>0.001</ixx>
          <ixy>0</ixy>
          <ixz>0</ixz>
          <iyy>0.001</iyy>
          <iyz>0</iyz>
          <izz>0.001</izz>
        </inertia>
      </inertial>
    </link>

    <link name="thruster2">
      <pose>0.14 0.092 0.0 -1.571 1.571 -2.356</pose>
      <visual name="thruster_prop_visual">
        <pose>0 0 0 -1.571 0 0</pose>
        <geometry>
          <mesh>
            <uri>model://orca4/meshes/t200_ccw_prop.dae</uri>
          </mesh>
        </geometry>
      </visual>
      <inertial>
        <mass>0.002</mass>
        <inertia>
          <ixx>0.001</ixx>
          <ixy>0</ixy>
          <ixz>0</ixz>
          <iyy>0.001</iyy>
          <iyz>0</iyz>
          <izz>0.001</izz>
        </inertia>
      </inertial>
    </link>

    <link name="thruster3">
      <pose>-0.15 -0.092 0.0 -1.571 1.571 0.785</pose>
      <visual name="thruster_prop_visual">
        <pose>0 0 0 1.571 0 0</pose>
        <geometry>
          <mesh>
            <uri>model://orca4/meshes/t200_cw_prop.dae</uri>
          </mesh>
        </geometry>
      </visual>
      <inertial>
        <mass>0.002</mass>
        <inertia>
          <ixx>0.001</ixx>
          <ixy>0</ixy>
          <ixz>0</ixz>
          <iyy>0.001</iyy>
          <iyz>0</iyz>
          <izz>0.001</izz>
        </inertia>
      </inertial>
    </link>

    <link name="thruster4">
      <pose>-0.15 0.092 0.0 -1.571 1.571 2.356</pose>
      <visual name="thruster_prop_visual">
        <pose>0 0 0 1.571 0 0</pose>
        <geometry>
          <mesh>
            <uri>model://orca4/meshes/t200_cw_prop.dae</uri>
          </mesh>
        </geometry>
      </visual>
      <inertial>
        <mass>0.002</mass>
        <inertia>
          <ixx>0.001</ixx>
          <ixy>0</ixy>
          <ixz>0</ixz>
          <iyy>0.001</iyy>
          <iyz>0</iyz>
          <izz>0.001</izz>
        </inertia>
      </inertial>
    </link>

    <link name="thruster5">
      <pose>0.118 -0.215 0.064 0 0 0</pose>
      <visual name="thruster_prop_visual">
        <pose>0 0 0 -1.571 0 1.571</pose>
        <geometry>
          <mesh>
            <uri>model://orca4/meshes/t200_ccw_prop.dae</uri>
          </mesh>
        </geometry>
      </visual>
      <inertial>
        <mass>0.002</mass>
        <inertia>
          <ixx>0.001</ixx>
          <ixy>0</ixy>
          <ixz>0</ixz>
          <iyy>0.001</iyy>
          <iyz>0</iyz>
          <izz>0.001</izz>
        </inertia>
      </inertial>
    </link>

    <link name="thruster6">
      <pose>0.118 0.215 0.064 0 0 0</pose>
      <visual name="thruster_prop_visual">
        <pose>0 0 0 1.571 0 1.571</pose>
        <geometry>
          <mesh>
            <uri>model://orca4/meshes/t200_cw_prop.dae</uri>
          </mesh>
        </geometry>
      </visual>
      <inertial>
        <mass>0.002</mass>
        <inertia>
          <ixx>0.001</ixx>
          <ixy>0</ixy>
          <ixz>0</ixz>
          <iyy>0.001</iyy>
          <iyz>0</iyz>
          <izz>0.001</izz>
        </inertia>
      </inertial>
    </link>

    <link name="thruster7">
      <pose>-0.118 -0.215 0.064 0 0 0</pose>
      <visual name="thruster_prop_visual">
        <pose>0 0 0 1.571 0 1.571</pose>
        <geometry>
          <mesh>
            <uri>model://orca4/meshes/t200_cw_prop.dae</uri>
          </mesh>
        </geometry>
      </visual>
      <inertial>
        <mass>0.002</mass>
        <inertia>
          <ixx>0.001</ixx>
          <ixy>0</ixy>
          <ixz>0</ixz>
          <iyy>0.001</iyy>
          <iyz>0</iyz>
          <izz>0.001</izz>
        </inertia>
      </inertial>
    </link>

    <link name="thruster8">
      <pose>-0.118 0.215 0.064 0 0 0</pose>
      <visual name="thruster_prop_visual">
        <pose>0 0 0 1.571 0 1.571</pose>
        <geometry>
          <mesh>
            <uri>model://orca4/meshes/t200_cw_prop.dae</uri>
          </mesh>
        </geometry>
      </visual>
      <inertial>
        <mass>0.002</mass>
        <inertia>
          <ixx>0.001</ixx>
          <ixy>0</ixy>
          <ixz>0</ixz>
          <iyy>0.001</iyy>
          <iyz>0</iyz>
          <izz>0.001</izz>
        </inertia>
      </inertial>
    </link>

    <joint name="thruster1_joint" type="revolute">
      <parent>base_link</parent>
      <child>thruster1</child>
      <axis>
        <xyz>0 0 -1</xyz>
      </axis>
    </joint>

    <joint name="thruster2_joint" type="revolute">
      <parent>base_link</parent>
      <child>thruster2</child>
      <axis>
        <xyz>0 0 -1</xyz>
      </axis>
    </joint>

    <joint name="thruster3_joint" type="revolute">
      <parent>base_link</parent>
      <child>thruster3</child>
      <axis>
        <xyz>0 0 -1</xyz>
      </axis>
    </joint>

    <joint name="thruster4_joint" type="revolute">
      <parent>base_link</parent>
      <child>thruster4</child>
      <axis>
        <xyz>0 0 -1</xyz>
      </axis>
    </joint>

    <joint name="thruster5_joint" type="revolute">
      <parent>base_link</parent>
      <child>thruster5</child>
      <axis>
        <xyz>0 0 -1</xyz>
      </axis>
    </joint>

    <joint name="thruster6_joint" type="revolute">
      <parent>base_link</parent>
      <child>thruster6</child>
      <axis>
        <xyz>0 0 -1</xyz>
      </axis>
    </joint>

    <joint name="thruster7_joint" type="revolute">
      <parent>base_link</parent>
      <child>thruster7</child>
      <axis>
        <xyz>0 0 -1</xyz>
      </axis>
    </joint>

    <joint name="thruster8_joint" type="revolute">
      <parent>base_link</parent>
      <child>thruster8</child>
      <axis>
        <xyz>0 0 -1</xyz>
      </axis>
    </joint>

    <plugin
        filename="gz-sim-thruster-system"
        name="gz::sim::systems::Thruster">
      <namespace>orca4</namespace>
      <joint_name>thruster1_joint</joint_name>
      <thrust_coefficient>0.02</thrust_coefficient>
      <fluid_density>1000.0</fluid_density>
      <propeller_diameter>0.1</propeller_diameter>
      <velocity_control>true</velocity_control>
      <use_angvel_cmd>False</use_angvel_cmd>
    </plugin>

    <plugin
        filename="gz-sim-thruster-system"
        name="gz::sim::systems::Thruster">
      <namespace>orca4</namespace>
      <joint_name>thruster2_joint</joint_name>
      <thrust_coefficient>0.02</thrust_coefficient>
      <fluid_density>1000.0</fluid_density>
      <propeller_diameter>0.1</propeller_diameter>
      <velocity_control>true</velocity_control>
      <use_angvel_cmd>False</use_angvel_cmd>
    </plugin>

    <plugin
        filename="gz-sim-thruster-system"
        name="gz::sim::systems::Thruster">
      <namespace>orca4</namespace>
      <joint_name>thruster3_joint</joint_name>
      <!-- Reverse spin to balance torque -->
      <thrust_coefficient>-0.02</thrust_coefficient>
      <fluid_density>1000.0</fluid_density>
      <propeller_diameter>0.1</propeller_diameter>
      <velocity_control>true</velocity_control>
      <use_angvel_cmd>False</use_angvel_cmd>
    </plugin>

    <plugin
        filename="gz-sim-thruster-system"
        name="gz::sim::systems::Thruster">
      <namespace>orca4</namespace>
      <joint_name>thruster4_joint</joint_name>
      <!-- Reverse spin to balance torque -->
      <thrust_coefficient>-0.02</thrust_coefficient>
      <fluid_density>1000.0</fluid_density>
      <propeller_diameter>0.1</propeller_diameter>
      <velocity_control>true</velocity_control>
      <use_angvel_cmd>False</use_angvel_cmd>
    </plugin>

    <plugin
        filename="gz-sim-thruster-system"
        name="gz::sim::systems::Thruster">
      <namespace>orca4</namespace>
      <joint_name>thruster5_joint</joint_name>
      <thrust_coefficient>0.02</thrust_coefficient>
      <fluid_density>1000.0</fluid_density>
      <propeller_diameter>0.1</propeller_diameter>
      <velocity_control>true</velocity_control>
      <use_angvel_cmd>False</use_angvel_cmd>
    </plugin>

    <plugin
        filename="gz-sim-thruster-system"
        name="gz::sim::systems::Thruster">
      <namespace>orca4</namespace>
      <joint_name>thruster6_joint</joint_name>
      <!-- Reverse spin to balance torque -->
      <thrust_coefficient>-0.02</thrust_coefficient>
      <fluid_density>1000.0</fluid_density>
      <propeller_diameter>0.1</propeller_diameter>
      <velocity_control>true</velocity_control>
      <use_angvel_cmd>False</use_angvel_cmd>
    </plugin>

    <plugin
        filename="gz-sim-thruster-system"
        name="gz::sim::systems::Thruster">
      <namespace>orca4</namespace>
      <joint_name>thruster7_joint</joint_name>
      <!-- Reverse spin to balance torque -->
      <thrust_coefficient>-0.02</thrust_coefficient>
      <fluid_density>1000.0</fluid_density>
      <propeller_diameter>0.1</propeller_diameter>
      <velocity_control>true</velocity_control>
      <use_angvel_cmd>False</use_angvel_cmd>
    </plugin>

    <plugin
        filename="gz-sim-thruster-system"
        name="gz::sim::systems::Thruster">
      <namespace>orca4</namespace>
      <joint_name>thruster8_joint</joint_name>
      <thrust_coefficient>0.02</thrust_coefficient>
      <fluid_density>1000.0</fluid_density>
      <propeller_diameter>0.1</propeller_diameter>
      <velocity_control>true</velocity_control>
      <use_angvel_cmd>False</use_angvel_cmd>
    </plugin>

    <plugin name="ArduPilotPlugin" filename="libArduPilotPlugin.so">
      <!-- Port settings -->
      <fdm_addr>127.0.0.1</fdm_addr>
      <fdm_port_in>9002</fdm_port_in>
      <connectionTimeoutMaxCount>5</connectionTimeoutMaxCount>
      <lock_step>1</lock_step>

      <!-- Transform from the Gazebo body frame (x-forward, y-left, z-up)
           to the ArduPilot body frame (x-forward, y-right, z-down) -->
      <modelXYZToAirplaneXForwardZDown>0 0 0 3.142 0 0</modelXYZToAirplaneXForwardZDown>

      <!-- Transform from the Gazebo world frame (ENU)
           to the ArduPilot world frame (NED) -->
      <gazeboXYZToNED>0 0 0 3.142 0 1.571</gazeboXYZToNED>

      <!-- Sensors -->
      <imuName>imu_sensor</imuName>
      <!-- <dvlName>teledyne_pathfinder_dvl</dvlName> -->
      <!-- Thrusters -->
      <control channel="0">
        <jointName>thruster1_joint</jointName>
        <servo_min>1100</servo_min>
        <servo_max>1900</servo_max>
        <type>COMMAND</type>
        <cmd_topic>/model/orca4/joint/thruster1_joint/cmd_thrust</cmd_topic>
        <offset>-0.5</offset>
        <multiplier>100</multiplier>
      </control>
      <control channel="1">
        <jointName>thruster2_joint</jointName>
        <servo_min>1100</servo_min>
        <servo_max>1900</servo_max>
        <type>COMMAND</type>
        <cmd_topic>/model/orca4/joint/thruster2_joint/cmd_thrust</cmd_topic>
        <offset>-0.5</offset>
        <multiplier>100</multiplier>
      </control>
      <control channel="2">
        <jointName>thruster3_joint</jointName>
        <servo_min>1100</servo_min>
        <servo_max>1900</servo_max>
        <type>COMMAND</type>
        <cmd_topic>/model/orca4/joint/thruster3_joint/cmd_thrust</cmd_topic>
        <offset>-0.5</offset>
        <multiplier>100</multiplier>
      </control>
      <control channel="3">
        <jointName>thruster4_joint</jointName>
        <servo_min>1100</servo_min>
        <servo_max>1900</servo_max>
        <type>COMMAND</type>
        <cmd_topic>/model/orca4/joint/thruster4_joint/cmd_thrust</cmd_topic>
        <offset>-0.5</offset>
        <multiplier>100</multiplier>
      </control>
      <control channel="4">
        <jointName>thruster5_joint</jointName>
        <servo_min>1100</servo_min>
        <servo_max>1900</servo_max>
        <type>COMMAND</type>
        <cmd_topic>/model/orca4/joint/thruster5_joint/cmd_thrust</cmd_topic>
        <offset>-0.5</offset>
        <multiplier>100</multiplier>
      </control>
      <control channel="5">
        <jointName>thruster6_joint</jointName>
        <servo_min>1100</servo_min>
        <servo_max>1900</servo_max>
        <type>COMMAND</type>
        <cmd_topic>/model/orca4/joint/thruster6_joint/cmd_thrust</cmd_topic>
        <offset>-0.5</offset>
        <multiplier>100</multiplier>
      </control>
      <control channel="6">
        <jointName>thruster7_joint</jointName>
        <servo_min>1100</servo_min>
        <servo_max>1900</servo_max>
        <type>COMMAND</type>
        <cmd_topic>/model/orca4/joint/thruster7_joint/cmd_thrust</cmd_topic>
        <offset>-0.5</offset>
        <multiplier>100</multiplier>
      </control>
      <control channel="7">
        <jointName>thruster8_joint</jointName>
        <servo_min>1100</servo_min>
        <servo_max>1900</servo_max>
        <type>COMMAND</type>
        <cmd_topic>/model/orca4/joint/thruster8_joint/cmd_thrust</cmd_topic>
        <offset>-0.5</offset>
        <multiplier>100</multiplier>
      </control>

    </plugin>
    <!-- Left camera link -->
    <link name="left_camera_link">
      <pose>-0.18 0.18 -0.06749999999999999 0 0 0</pose>
      <visual name="left_camera_tube">
        <transparency>0.0</transparency>
        <geometry>
          <cylinder>
            <length>0.135</length>
            <radius>0.0275</radius>
          </cylinder>
        </geometry>
      </visual>
      <sensor name="left_camera" type="camera">
        <pose>0 0 -0.08750000000000001 0 1.5707963267948966 0</pose>
        <camera>
          <vertical_fov>1.3962634</vertical_fov>
          <image>
            <width>3840</width>
            <height>1440</height>
          </image>
          <clip>
            <near>0.02</near>
            <far>5</far>
          </clip>
        </camera>
        <always_on>1</always_on>
        <update_rate>10</update_rate>
        <visualize>true</visualize>
        <topic>stereo_left</topic>
      </sensor>
      <inertial>
        <mass>0.001</mass>
        <inertia>
          <ixx>0.001</ixx>
          <ixy>0</ixy>
          <ixz>0</ixz>
          <iyy>0.001</iyy>
          <iyz>0</iyz>
          <izz>0.001</izz>
        </inertia>
      </inertial>
    </link>



    <!-- Attach left_camera_link to base_link -->
    <joint name="left_camera_joint" type="fixed">
      <!-- <pose>-0.15 0.18 -0.0675 0 1.5707963267948966 0</pose> -->
      <parent>base_link</parent>
      <child>left_camera_link</child>
    </joint>

    <!-- Right camera link -->
    <link name="right_camera_link">
      <pose>-0.18 -0.18 -0.06749999999999999 0 0 0</pose>
      <visual name="right_camera_tube">
        <transparency>0.0</transparency>
        <geometry>
          <cylinder>
            <length>0.135</length>
            <radius>0.0275</radius>
          </cylinder>
        </geometry>
      </visual>
      <sensor name="right_camera" type="camera">
        <pose>0 0 -0.08750000000000001 0 1.5707963267948966 0</pose>
        <camera>
          <vertical_fov>1.3962634</vertical_fov>
          <image>
            <width>3840</width>
            <height>1440</height>
          </image>
          <clip>
            <near>0.02</near>
            <far>5</far>
          </clip>
        </camera>
        <always_on>1</always_on>
        <update_rate>10</update_rate>
        <visualize>true</visualize>
        <topic>stereo_right</topic>
      </sensor>
      <inertial>
        <mass>0.001</mass>
        <inertia>
          <ixx>0.001</ixx>
          <ixy>0</ixy>
          <ixz>0</ixz>
          <iyy>0.001</iyy>
          <iyz>0</iyz>
          <izz>0.001</izz>
        </inertia>
      </inertial>
    </link>

  
    <!-- Attach right_camera_link to base_link -->
    <joint name="right_camera_joint" type="fixed">
      <!-- <pose>-0.15 -0.18 -0.0675 0 1.5707963267948966 0</pose> -->
      <parent>base_link</parent>
      <child>right_camera_link</child>
    </joint>

    <!-- Publish the ground-truth pose for rviz -->
    <plugin
        filename="gz-sim-odometry-publisher-system"
        name="gz::sim::systems::OdometryPublisher">
      <odom_frame>map</odom_frame>
      <robot_base_frame>orca4</robot_base_frame>
      <dimensions>3</dimensions>
    </plugin>

    <link name="acoustic_pinger_link">
      <!-- Visual Representation -->
      <!-- <visual name="acoustic_pinger_visual">
          <pose>0 0 0 0 0 0</pose> 
          <geometry>
              <cylinder>
                  <radius>0.05</radius> 
                  <length>0.2</length>  
              </cylinder>
          </geometry>
          <material>
              <ambient>1 0 0 1</ambient> 
          </material>
      </visual> -->

    <!-- Inertial Properties -->
      <inertial>
          <pose>0 0 0 0 0 0</pose> <!-- Adjust pose to center mass correctly -->
          <mass>1.0</mass> <!-- Mass of the pinger in kilograms -->
          <inertia>
              <!-- These values need to be calculated based on the geometry and mass distribution -->
              <ixx>0.0001</ixx> <!-- Moment of inertia around X-axis -->
              <iyy>0.0001</iyy> <!-- Moment of inertia around Y-axis -->
              <izz>0.0001</izz> <!-- Moment of the inertia around Z-axis, can be different if needed -->
          </inertia>
      </inertial>
  </link>

  <plugin filename="libAcousticPingerPlugin.so" name="vrx::AcousticPingerPlugin">
    <topic>/bluerov2_heavy/sensors/acoustics/receiver/range_bearing</topic>
    <set_position_topic>/pinger/set_pinger_position</set_position_topic>
    <!-- Noise and other parameters can be defined here -->
  </plugin>

    <link name="water_linked_dvl_a50_base_link">
      <pose>0 0 -0.2 0 0 0</pose>
      <inertial>
        <pose>0 0 0 0 0 0</pose>
        <mass>0.17</mass>
        <inertia>
          <ixx>0.0195872</ixx>
          <ixy>0</ixy>
          <ixz>0</ixz>
          <iyy>0.0195872</iyy>
          <iyz>0</iyz>
          <izz>0.0151357</izz>
        </inertia>
      </inertial>
      <velocity_decay/>
      <gravity>1</gravity>
      <velocity_decay/>

      <sensor
        name="water_linked_dvl_a50" type="custom"
        gz:type="dvl">
        <pose>0 0 0.025 0 0 1.57079632679</pose>
        <always_on>1</always_on>
        <update_rate>8</update_rate>
        <topic>/dvl/velocity</topic>
        <gz:dvl>
          <type>phased_array</type>
          <arrangement degrees="true">
            <beam id="1">
              <aperture>4.3</aperture>
              <rotation>-135</rotation>
              <tilt>15</tilt>
            </beam>
            <beam>
              <aperture>4.3</aperture>
              <rotation>135</rotation>
              <tilt>15</tilt>
            </beam>
            <beam>
              <aperture>4.3</aperture>
              <rotation>45</rotation>
              <tilt>15</tilt>
            </beam>
            <beam>
              <aperture>4.3</aperture>
              <rotation>-45</rotation>
              <tilt>15</tilt>
            </beam>
          </arrangement>
          <tracking>
            <!-- <water_mass_mode>
              <when>best</when>
              <water_velocity>
                <x>0.</x>
                <y>0.</y>
                <z>0.</z>
              </water_velocity>
              <boundaries>
                <near>10.</near>
                <far>100.</far>
              </boundaries>
              <bins>10</bins>
              <noise type="gaussian">
                <stddev>0.015</stddev>
              </noise>
              <visualize>true</visualize>
            </water_mass_mode> -->
            <bottom_mode>
              <when>best</when>
              <noise type="gaussian">
                <stddev>0.005</stddev>
              </noise>
              <visualize>true</visualize>
            </bottom_mode>
          </tracking>
          <maximum_range>50.</maximum_range>
          <minimum_range>0.05</minimum_range>
          <!-- ENU to FSD -->
          <reference_frame>0 0 0 3.14 0 -1.57</reference_frame>
        </gz:dvl>
      </sensor>

      <self_collide>0</self_collide>
      <enable_wind>0</enable_wind>
      <kinematic>0</kinematic>
      <visual name="water_linked_dvl_a50_base_link_visual">
        <pose>0 0 0 0 0 3.14159</pose>
        <geometry>
          <mesh>
            <scale>1 1 1</scale>
            <!-- Mesh is actually for a Nortek DVL1000-4000m for now -->
            <!-- <uri>model://meshes/nortek_water_linked_dvl_a50_300/water_linked_dvl_a50-300m.dae</uri> -->
            <uri>model://meshes/water_linked_dvl_a50/water_linked_dvl_a50.dae</uri>
          </mesh>
        </geometry>
        <transparency>0</transparency>
        <cast_shadows>1</cast_shadows>
      </visual>
      <collision name="water_linked_dvl_a50_base_link_collision">
        <laser_retro>0</laser_retro>
        <max_contacts>10</max_contacts>
        <pose>0 0 0 3.14159 0 0</pose>
        <geometry>
          <cylinder>
            <radius>0.033</radius>
            <length>0.025</length>
          </cylinder>
        </geometry>
        <surface>
          <friction>
            <ode>
              <mu>1</mu>
              <mu2>1</mu2>
              <fdir1>0 0 0</fdir1>
              <slip1>0</slip1>
              <slip2>0</slip2>
            </ode>
            <torsional>
              <coefficient>1</coefficient>
              <patch_radius>0</patch_radius>
              <surface_radius>0</surface_radius>
              <use_patch_radius>1</use_patch_radius>
              <ode>
                <slip>0</slip>
              </ode>
            </torsional>
          </friction>
          <bounce>
            <restitution_coefficient>0</restitution_coefficient>
            <threshold>1e+06</threshold>
          </bounce>
          <contact>
            <collide_without_contact>0</collide_without_contact>
            <collide_without_contact_bitmask>1</collide_without_contact_bitmask>
            <collide_bitmask>1</collide_bitmask>
            <ode>
              <soft_cfm>0</soft_cfm>
              <soft_erp>0.2</soft_erp>
              <kp>1e+13</kp>
              <kd>1</kd>
              <max_vel>0.01</max_vel>
              <min_depth>0</min_depth>
            </ode>
            <bullet>
              <split_impulse>1</split_impulse>
              <split_impulse_penetration_threshold>-0.01</split_impulse_penetration_threshold>
              <soft_cfm>0</soft_cfm>
              <soft_erp>0.2</soft_erp>
              <kp>1e+13</kp>
              <kd>1</kd>
            </bullet>
          </contact>
        </surface>
      </collision>
    </link>

    <joint name="water_linked_dvl_a50_base_link_joint" type="fixed">
      <parent>base_link</parent>
      <child>water_linked_dvl_a50_base_link</child>
    </joint>
        
  <allow_auto_disable>1</allow_auto_disable>
  <plugin
      filename="DVLBridge"
      name="dave_ros_gz_plugins::DVLBridge">
      <topic>/dvl/velocity</topic>
    </plugin>

  </model>
</sdf>